<?xml version='1.0'?>
<sdf version='1.6'>
  <model name='conveyor'>
    <!--
    This model is identical to the extra heavy duty table in nearly
    every respect except that the collision tags are present only for
    the surface link. This leads to a large speedup in simulations
    involving the table due to a decrease in number of collision
    checks needed.
    -->
    <link name='base_link'>

      <visual name='visual_base'>
      <pose frame=''>0 0 0 0 0 0</pose>
        <geometry>
          <box>
            <size>0.05 0.05 0.05</size>
          </box>
        </geometry>
        <material>
          <diffuse>1 0.5 0 1.0</diffuse>
        </material>
      </visual>
    </link>

    <!-- <link name='cylinder_link'>
      <gravity>0</gravity>

      <visual name='visual_cylinder'>
        <pose frame=''>0 -1.5 0 0 -1.57 0</pose>
          <geometry>
            <cylinder>
              <radius>0.136</radius>
              <length>0.5</length>
            </cylinder>
          </geometry>
          <material>
            <diffuse>1 0.5 0 1.0</diffuse>
          </material>
        </visual>
    </link> -->

    <link name='first_link'>
      <visual name='visual_1'>
      <pose frame=''>0 0 0 0 0 0</pose>
        <geometry>
          <box> 
            <!-- <size>0.05 0.05 0.275</size> -->
            <size>0.05 0.05 0.13</size>

          </box>
        </geometry>
        <material>
          <diffuse>0 0 1 1</diffuse>
        </material>
      </visual>
    </link>

    <!-- <link name='connector_link_01'>
      <visual name='visual_01'>
        <pose> 0 0 0.1 0 0 0</pose>
        <geometry>
          <box>
            <size>0.05 0.05 0.05</size>
          </box>
        </geometry>
        <material>
          <diffuse>1 1 0 1.0</diffuse>
        </material>
      </visual>
    </link> -->

    <link name='collision_link1'>
      <inertial>
        <mass>5</mass>
        <inertia>
          <ixx>1</ixx>
          <ixy>0</ixy>
          <ixz>0</ixz>
          <iyy>1</iyy>
          <iyz>0</iyz>
          <izz>1</izz>
        </inertia>
      </inertial>

      <self_collide>0</self_collide>
      <!-- <kinematic>1</kinematic> -->
       <visual name='visual_01'>
        <pose frame=''>0 0 0.075 0 0 0</pose>
        <geometry>
          <box>
            <size>0.6 0.05 0.02</size>
          </box>
        </geometry>
        <material>
          <diffuse>0 0.5 0 1.0</diffuse>
        </material>
      </visual>

      <collision name='surface'>
        <pose frame=''>0 0 0.075 0 0 0</pose>
        <laser_retro>0</laser_retro>
        <max_contacts>10</max_contacts>
        <geometry>
          <box>
            <size>0.6 0.05 0.02</size>
          </box>
        </geometry>
        <surface>
          <friction>
            <ode>
              <mu>0.6</mu>
              <mu2>0.6</mu2>
              <fdir1>0 0 0</fdir1>
              <slip1>0</slip1>
              <slip2>0</slip2>
            </ode>
            <torsional>
              <coefficient>1</coefficient>
              <patch_radius>0</patch_radius>
              <surface_radius>0</surface_radius>
              <use_patch_radius>1</use_patch_radius>
              <ode>
                <slip>0</slip>
              </ode>
            </torsional>
          </friction>
          <bounce>
            <restitution_coefficient>0</restitution_coefficient>
            <threshold>1e+06</threshold>
          </bounce>
          <contact>
            <collide_without_contact>0</collide_without_contact>
            <collide_without_contact_bitmask>1</collide_without_contact_bitmask>
            <collide_bitmask>1</collide_bitmask>
            <ode>
              <soft_cfm>0</soft_cfm>
              <soft_erp>0.2</soft_erp>
              <kp>1e+13</kp>
              <kd>1</kd>
              <max_vel>0.01</max_vel>
              <min_depth>0</min_depth>
            </ode>
            <bullet>
              <split_impulse>1</split_impulse>
              <split_impulse_penetration_threshold>-0.01</split_impulse_penetration_threshold>
              <soft_cfm>0</soft_cfm>
              <soft_erp>0.2</soft_erp>
              <kp>1e+13</kp>
              <kd>1</kd>
            </bullet>
          </contact>
        </surface>
      </collision> 
    </link> 

    <link name='collision_frame_1'>
      <pose frame=''>0 0.025  0.06875 0 0 0</pose>
      <visual name='visual_02'>
        <geometry>
          <box>
            <size>0.01 0.01 0.01</size>
          </box>
        </geometry>
        <material>
          <diffuse>0 1 1 1.0</diffuse>
        </material>
      </visual>
    </link>


    <!-- When you uncomment this, make sure to increase the frame number --> 
    <link name='collision_link2'>
      <pose frame=''>0 0.05 0.075 0 0 0</pose>

      <inertial>
        <mass>0.5</mass>
        <inertia>
          <ixx>1</ixx>
          <ixy>0</ixy>
          <ixz>0</ixz>
          <iyy>0.1</iyy>
          <iyz>0</iyz>
          <izz>1</izz>
        </inertia>
      </inertial>
      <gravity>0</gravity>
      <self_collide>0</self_collide>
      <kinematic>1</kinematic>
       <visual name='visual_02'>
        <geometry>
          <box>
            <size>0.6 0.05 0.02</size>
          </box>
        </geometry>
        <material>
          <diffuse>0 0.5 0 1.0</diffuse>
        </material>
      </visual>

      <collision name='surface2'>
        <laser_retro>0</laser_retro>
        <max_contacts>10</max_contacts>
        <geometry>
          <box>
            <size>0.6 0.05 0.02</size>
          </box>
        </geometry>
        <surface>
          <friction>
            <ode>
              <mu>0.6</mu>
              <mu2>0.6</mu2>
              <fdir1>0 0 0</fdir1>
              <slip1>0</slip1>
              <slip2>0</slip2>
            </ode>
            <torsional>
              <coefficient>1</coefficient>
              <patch_radius>0</patch_radius>
              <surface_radius>0</surface_radius>
              <use_patch_radius>1</use_patch_radius>
              <ode>
                <slip>0</slip>
              </ode>
            </torsional>
          </friction>
          <bounce>
            <restitution_coefficient>0</restitution_coefficient>
            <threshold>1e+06</threshold>
          </bounce>
          <contact>
            <collide_without_contact>0</collide_without_contact>
            <collide_without_contact_bitmask>1</collide_without_contact_bitmask>
            <collide_bitmask>1</collide_bitmask>
            <ode>
              <soft_cfm>0</soft_cfm>
              <soft_erp>0.2</soft_erp>
              <kp>1e+13</kp>
              <kd>1</kd>
              <max_vel>0.01</max_vel>
              <min_depth>0</min_depth>
            </ode>
            <bullet>
              <split_impulse>1</split_impulse>
              <split_impulse_penetration_threshold>-0.01</split_impulse_penetration_threshold>
              <soft_cfm>0</soft_cfm>
              <soft_erp>0.2</soft_erp>
              <kp>1e+13</kp>
              <kd>1</kd>
            </bullet>
          </contact>
        </surface>
      </collision> 
    </link>  

    <link name='collision_frame_2'>
      <pose frame=''>0 0.075  0.06875 0 0 0</pose>
      <visual name='visual_02'>
        <geometry>
          <box>
            <size>0.01 0.01 0.01</size>
          </box>
        </geometry>
        <material>
          <diffuse>0 1 1 1.0</diffuse>
        </material>
      </visual>
    </link>

    <link name='collision_link3'>
      <pose frame=''>0 0.1 0.075 0 0 0</pose>

      <inertial>
        <mass>0.5</mass>
        <inertia>
          <ixx>1</ixx>
          <ixy>0</ixy>
          <ixz>0</ixz>
          <iyy>0.1</iyy>
          <iyz>0</iyz>
          <izz>1</izz>
        </inertia>
      </inertial>
      <gravity>0</gravity>
      <self_collide>0</self_collide>
      <kinematic>1</kinematic>
       <visual name='visual_03'>
        <geometry>
          <box>
            <size>0.6 0.05 0.02</size>
          </box>
        </geometry>
        <material>
          <diffuse>0 0.5 0 1.0</diffuse>
        </material>
      </visual>

      <collision name='surface3'>
        <laser_retro>0</laser_retro>
        <max_contacts>10</max_contacts>
        <geometry>
          <box>
            <size>0.6 0.05 0.02</size>
          </box>
        </geometry>
        <surface>
          <friction>
            <ode>
              <mu>0.6</mu>
              <mu2>0.6</mu2>
              <fdir1>0 0 0</fdir1>
              <slip1>0</slip1>
              <slip2>0</slip2>
            </ode>
            <torsional>
              <coefficient>1</coefficient>
              <patch_radius>0</patch_radius>
              <surface_radius>0</surface_radius>
              <use_patch_radius>1</use_patch_radius>
              <ode>
                <slip>0</slip>
              </ode>
            </torsional>
          </friction>
          <bounce>
            <restitution_coefficient>0</restitution_coefficient>
            <threshold>1e+06</threshold>
          </bounce>
          <contact>
            <collide_without_contact>0</collide_without_contact>
            <collide_without_contact_bitmask>1</collide_without_contact_bitmask>
            <collide_bitmask>1</collide_bitmask>
            <ode>
              <soft_cfm>0</soft_cfm>
              <soft_erp>0.2</soft_erp>
              <kp>1e+13</kp>
              <kd>1</kd>
              <max_vel>0.01</max_vel>
              <min_depth>0</min_depth>
            </ode>
            <bullet>
              <split_impulse>1</split_impulse>
              <split_impulse_penetration_threshold>-0.01</split_impulse_penetration_threshold>
              <soft_cfm>0</soft_cfm>
              <soft_erp>0.2</soft_erp>
              <kp>1e+13</kp>
              <kd>1</kd>
            </bullet>
          </contact>
        </surface>
      </collision> 
    </link>  

<link name='collision_frame_3'>
      <pose frame=''>0 0.125  0.06875 0 0 0</pose>
      <visual name='visual_03'>
        <geometry>
          <box>
            <size>0.01 0.01 0.01</size>
          </box>
        </geometry>
        <material>
          <diffuse>0 1 1 1.0</diffuse>
        </material>
      </visual>
    </link>

    <link name='collision_link4'>
      <pose frame=''>0 0.15 0.075 0 0 0</pose>

      <inertial>
        <mass>0.5</mass>
        <inertia>
          <ixx>1</ixx>
          <ixy>0</ixy>
          <ixz>0</ixz>
          <iyy>0.1</iyy>
          <iyz>0</iyz>
          <izz>1</izz>
        </inertia>
      </inertial>
      <gravity>0</gravity>
      <self_collide>0</self_collide>
      <kinematic>1</kinematic>
       <visual name='visual_04'>
        <geometry>
          <box>
            <size>0.6 0.05 0.02</size>
          </box>
        </geometry>
        <material>
          <diffuse>0 0.5 0 1.0</diffuse>
        </material>
      </visual>

      <collision name='surface4'>
        <laser_retro>0</laser_retro>
        <max_contacts>10</max_contacts>
        <geometry>
          <box>
            <size>0.6 0.05 0.02</size>
          </box>
        </geometry>
        <surface>
          <friction>
            <ode>
              <mu>0.6</mu>
              <mu2>0.6</mu2>
              <fdir1>0 0 0</fdir1>
              <slip1>0</slip1>
              <slip2>0</slip2>
            </ode>
            <torsional>
              <coefficient>1</coefficient>
              <patch_radius>0</patch_radius>
              <surface_radius>0</surface_radius>
              <use_patch_radius>1</use_patch_radius>
              <ode>
                <slip>0</slip>
              </ode>
            </torsional>
          </friction>
          <bounce>
            <restitution_coefficient>0</restitution_coefficient>
            <threshold>1e+06</threshold>
          </bounce>
          <contact>
            <collide_without_contact>0</collide_without_contact>
            <collide_without_contact_bitmask>1</collide_without_contact_bitmask>
            <collide_bitmask>1</collide_bitmask>
            <ode>
              <soft_cfm>0</soft_cfm>
              <soft_erp>0.2</soft_erp>
              <kp>1e+13</kp>
              <kd>1</kd>
              <max_vel>0.01</max_vel>
              <min_depth>0</min_depth>
            </ode>
            <bullet>
              <split_impulse>1</split_impulse>
              <split_impulse_penetration_threshold>-0.01</split_impulse_penetration_threshold>
              <soft_cfm>0</soft_cfm>
              <soft_erp>0.2</soft_erp>
              <kp>1e+13</kp>
              <kd>1</kd>
            </bullet>
          </contact>
        </surface>
      </collision> 
    </link>  

    <link name='collision_frame_4'>
      <pose frame=''>0 0.175  0.06875 0 0 0</pose>
      <visual name='visual_04'>
        <geometry>
          <box>
            <size>0.01 0.01 0.01</size>
          </box>
        </geometry>
        <material>
          <diffuse>0 1 1 1.0</diffuse>
        </material>
      </visual>
    </link>

    <link name='collision_link5'>
      <pose frame=''>0 0.2 0.075 0 0 0</pose>

      <inertial>
        <mass>0.5</mass>
        <inertia>
          <ixx>1</ixx>
          <ixy>0</ixy>
          <ixz>0</ixz>
          <iyy>0.1</iyy>
          <iyz>0</iyz>
          <izz>1</izz>
        </inertia>
      </inertial>
      <gravity>0</gravity>
      <self_collide>0</self_collide>
      <kinematic>1</kinematic>
       <visual name='visual_05'>
        <geometry>
          <box>
            <size>0.6 0.05 0.02</size>
          </box>
        </geometry>
        <material>
          <diffuse>0 0.5 0 1.0</diffuse>
        </material>
      </visual>

      <collision name='surface5'>
        <laser_retro>0</laser_retro>
        <max_contacts>10</max_contacts>
        <geometry>
          <box>
            <size>0.6 0.05 0.02</size>
          </box>
        </geometry>
        <surface>
          <friction>
            <ode>
              <mu>0.6</mu>
              <mu2>0.6</mu2>
              <fdir1>0 0 0</fdir1>
              <slip1>0</slip1>
              <slip2>0</slip2>
            </ode>
            <torsional>
              <coefficient>1</coefficient>
              <patch_radius>0</patch_radius>
              <surface_radius>0</surface_radius>
              <use_patch_radius>1</use_patch_radius>
              <ode>
                <slip>0</slip>
              </ode>
            </torsional>
          </friction>
          <bounce>
            <restitution_coefficient>0</restitution_coefficient>
            <threshold>1e+06</threshold>
          </bounce>
          <contact>
            <collide_without_contact>0</collide_without_contact>
            <collide_without_contact_bitmask>1</collide_without_contact_bitmask>
            <collide_bitmask>1</collide_bitmask>
            <ode>
              <soft_cfm>0</soft_cfm>
              <soft_erp>0.2</soft_erp>
              <kp>1e+13</kp>
              <kd>1</kd>
              <max_vel>0.01</max_vel>
              <min_depth>0</min_depth>
            </ode>
            <bullet>
              <split_impulse>1</split_impulse>
              <split_impulse_penetration_threshold>-0.01</split_impulse_penetration_threshold>
              <soft_cfm>0</soft_cfm>
              <soft_erp>0.2</soft_erp>
              <kp>1e+13</kp>
              <kd>1</kd>
            </bullet>
          </contact>
        </surface>
      </collision> 
    </link>  

    <link name='collision_frame_5'>
      <pose frame=''>0 0.225  0.06875 0 0 0</pose>
      <visual name='visual_05'>
        <geometry>
          <box>
            <size>0.01 0.01 0.01</size>
          </box>
        </geometry>
        <material>
          <diffuse>0 1 1 1.0</diffuse>
        </material>
      </visual>
    </link>

    <link name='collision_link6'>
      <pose frame=''>0 0.25 0.075 0 0 0</pose>

      <inertial>
        <mass>0.5</mass>
        <inertia>
          <ixx>1</ixx>
          <ixy>0</ixy>
          <ixz>0</ixz>
          <iyy>0.1</iyy>
          <iyz>0</iyz>
          <izz>1</izz>
        </inertia>
      </inertial>
      <gravity>0</gravity>
      <self_collide>0</self_collide>
      <kinematic>1</kinematic>
       <visual name='visual_06'>
        <geometry>
          <box>
            <size>0.6 0.05 0.02</size>
          </box>
        </geometry>
        <material>
          <diffuse>0 0.5 0 1.0</diffuse>
        </material>
      </visual>

      <collision name='surface6'>
        <laser_retro>0</laser_retro>
        <max_contacts>10</max_contacts>
        <geometry>
          <box>
            <size>0.6 0.05 0.02</size>
          </box>
        </geometry>
        <surface>
          <friction>
            <ode>
              <mu>0.6</mu>
              <mu2>0.6</mu2>
              <fdir1>0 0 0</fdir1>
              <slip1>0</slip1>
              <slip2>0</slip2>
            </ode>
            <torsional>
              <coefficient>1</coefficient>
              <patch_radius>0</patch_radius>
              <surface_radius>0</surface_radius>
              <use_patch_radius>1</use_patch_radius>
              <ode>
                <slip>0</slip>
              </ode>
            </torsional>
          </friction>
          <bounce>
            <restitution_coefficient>0</restitution_coefficient>
            <threshold>1e+06</threshold>
          </bounce>
          <contact>
            <collide_without_contact>0</collide_without_contact>
            <collide_without_contact_bitmask>1</collide_without_contact_bitmask>
            <collide_bitmask>1</collide_bitmask>
            <ode>
              <soft_cfm>0</soft_cfm>
              <soft_erp>0.2</soft_erp>
              <kp>1e+13</kp>
              <kd>1</kd>
              <max_vel>0.01</max_vel>
              <min_depth>0</min_depth>
            </ode>
            <bullet>
              <split_impulse>1</split_impulse>
              <split_impulse_penetration_threshold>-0.01</split_impulse_penetration_threshold>
              <soft_cfm>0</soft_cfm>
              <soft_erp>0.2</soft_erp>
              <kp>1e+13</kp>
              <kd>1</kd>
            </bullet>
          </contact>
        </surface>
      </collision> 
    </link>  

    <link name='collision_frame_6'>
      <pose frame=''>0 0.275  0.06875 0 0 0</pose>
      <visual name='visual_06'>
        <geometry>
          <box>
            <size>0.01 0.01 0.01</size>
          </box>
        </geometry>
        <material>
          <diffuse>0 1 1 1.0</diffuse>
        </material>
      </visual>
    </link>

    <link name='collision_link7'>
      <pose frame=''>0 0.3 0.075 0 0 0</pose>

      <inertial>
        <mass>0.5</mass>
        <inertia>
          <ixx>1</ixx>
          <ixy>0</ixy>
          <ixz>0</ixz>
          <iyy>0.1</iyy>
          <iyz>0</iyz>
          <izz>1</izz>
        </inertia>
      </inertial>
      <gravity>0</gravity>
      <self_collide>0</self_collide>
      <kinematic>1</kinematic>
       <visual name='visual_07'>
        <geometry>
          <box>
            <size>0.6 0.05 0.02</size>
          </box>
        </geometry>
        <material>
          <diffuse>0 0.5 0 1.0</diffuse>
        </material>
      </visual>

      <collision name='surface7'>
        <laser_retro>0</laser_retro>
        <max_contacts>10</max_contacts>
        <geometry>
          <box>
            <size>0.6 0.05 0.02</size>
          </box>
        </geometry>
        <surface>
          <friction>
            <ode>
              <mu>0.6</mu>
              <mu2>0.6</mu2>
              <fdir1>0 0 0</fdir1>
              <slip1>0</slip1>
              <slip2>0</slip2>
            </ode>
            <torsional>
              <coefficient>1</coefficient>
              <patch_radius>0</patch_radius>
              <surface_radius>0</surface_radius>
              <use_patch_radius>1</use_patch_radius>
              <ode>
                <slip>0</slip>
              </ode>
            </torsional>
          </friction>
          <bounce>
            <restitution_coefficient>0</restitution_coefficient>
            <threshold>1e+06</threshold>
          </bounce>
          <contact>
            <collide_without_contact>0</collide_without_contact>
            <collide_without_contact_bitmask>1</collide_without_contact_bitmask>
            <collide_bitmask>1</collide_bitmask>
            <ode>
              <soft_cfm>0</soft_cfm>
              <soft_erp>0.2</soft_erp>
              <kp>1e+13</kp>
              <kd>1</kd>
              <max_vel>0.01</max_vel>
              <min_depth>0</min_depth>
            </ode>
            <bullet>
              <split_impulse>1</split_impulse>
              <split_impulse_penetration_threshold>-0.01</split_impulse_penetration_threshold>
              <soft_cfm>0</soft_cfm>
              <soft_erp>0.2</soft_erp>
              <kp>1e+13</kp>
              <kd>1</kd>
            </bullet>
          </contact>
        </surface>
      </collision> 
    </link>  

    <joint name="zeroth_joint" type="prismatic">
      <parent>base_link</parent>
      <child>first_link</child>
      <axis>
        <dynamics>
          <friction>9</friction>
          <damping>5</damping>
          <spring_stiffness>10</spring_stiffness>
        </dynamics>
        <xyz>0 1 0</xyz>
      </axis>
    </joint>

    <joint name="first_joint" type="revolute">
      <parent>first_link</parent>
      <child>collision_link1</child>
      <axis>
        <dynamics>
          <friction>9</friction>
          <damping>5</damping>
          <spring_stiffness>10</spring_stiffness>
        </dynamics>
        <xyz>1 0 0</xyz>
      </axis>
    </joint>

    <!-- <joint name="cyl_joint" type="fixed">
      <parent>base_link</parent>
      <child>cylinder_link</child>
    </joint> -->

    <joint name="collision_to_frame_extention" type="fixed">
      <parent>collision_link1</parent>
      <child>collision_frame_1</child>
    </joint>

    <joint name="second_joint" type="revolute">
      <parent>collision_frame_1</parent>
      <child>collision_link2</child>
      <pose>0 -0.025 -0.0125 0 0 0</pose>
      <axis>
        <dynamics>
          <friction>9</friction>
          <damping>5</damping>
          <spring_stiffness>10</spring_stiffness>
        </dynamics>
        <xyz>1 0 0</xyz>
      </axis>
    </joint>     

    <joint name="collision_to_frame_extention2" type="fixed">
      <parent>collision_link2</parent>
      <child>collision_frame_2</child>
    </joint>

    <joint name="third_joint" type="revolute">
      <parent>collision_frame_2</parent>
      <child>collision_link3</child>
      <pose>0 -0.025 -0.0125 0 0 0</pose>
      <axis>
        <dynamics>
          <friction>9</friction>
          <damping>5</damping>
          <spring_stiffness>10</spring_stiffness>
        </dynamics>
        <xyz>1 0 0</xyz>
      </axis>
    </joint>  

    <joint name="collision_to_frame_extention3" type="fixed">
      <parent>collision_link3</parent>
      <child>collision_frame_3</child>
    </joint>

    <joint name="fourth_joint" type="revolute">
      <parent>collision_frame_3</parent>
      <child>collision_link4</child>
      <pose>0 -0.025 -0.0125 0 0 0</pose>
      <axis>
        <dynamics>
          <friction>9</friction>
          <damping>5</damping>
          <spring_stiffness>10</spring_stiffness>
        </dynamics>
        <xyz>1 0 0</xyz>
      </axis>
    </joint>  

    <joint name="collision_to_frame_extention4" type="fixed">
      <parent>collision_link4</parent>
      <child>collision_frame_4</child>
    </joint>

    <joint name="fifth_joint" type="revolute">
      <parent>collision_frame_4</parent>
      <child>collision_link5</child>
      <pose>0 -0.025 -0.0125 0 0 0</pose>
      <axis>
        <dynamics>
          <friction>9</friction>
          <damping>5</damping>
          <spring_stiffness>10</spring_stiffness>
        </dynamics>
        <xyz>1 0 0</xyz>
      </axis>
    </joint> 

    <joint name="collision_to_frame_extention5" type="fixed">
      <parent>collision_link5</parent>
      <child>collision_frame_5</child>
    </joint>

    <joint name="sixth_joint" type="revolute">
      <parent>collision_frame_5</parent>
      <child>collision_link6</child>
      <pose>0 -0.025 -0.0125 0 0 0</pose>
      <axis>
        <dynamics>
          <friction>9</friction>
          <damping>5</damping>
          <spring_stiffness>10</spring_stiffness>
        </dynamics>
        <xyz>1 0 0</xyz>
      </axis>
    </joint>  

    <joint name="collision_to_frame_extention6" type="fixed">
      <parent>collision_link6</parent>
      <child>collision_frame_6</child>
    </joint>

    <joint name="seventh_joint" type="revolute">
      <parent>collision_frame_6</parent>
      <child>collision_link7</child>
      <pose>0 -0.025 -0.0125 0 0 0</pose>
      <axis>
        <dynamics>
          <friction>9</friction>
          <damping>5</damping>
          <spring_stiffness>10</spring_stiffness>
        </dynamics>
        <xyz>1 0 0</xyz>
      </axis>
    </joint>  


    <transmission name="tran_0">
      <robotNamespace>/conveyor</robotNamespace>
      <type>transmission_interface/SimpleTransmission</type>
      <joint name="zeroth_joint">
        <hardwareInterface>PositionJointInterface</hardwareInterface>
      </joint>
      <actuator name="motor_0">
        <hardwareInterface>PositionJointInterface</hardwareInterface>
        <mechanicalReduction>1</mechanicalReduction>
      </actuator>
    </transmission>

    <transmission name="tran_1">
      <robotNamespace>/conveyor</robotNamespace>
      <type>transmission_interface/SimpleTransmission</type>
      <joint name="first_joint">
        <hardwareInterface>PositionJointInterface</hardwareInterface>
      </joint>
      <actuator name="motor_1">
        <hardwareInterface>PositionJointInterface</hardwareInterface>
        <mechanicalReduction>1</mechanicalReduction>
      </actuator>
    </transmission>

    <transmission name="tran_2">
      <robotNamespace>/conveyor</robotNamespace>
      <type>transmission_interface/SimpleTransmission</type>
      <joint name="second_joint">
        <hardwareInterface>PositionJointInterface</hardwareInterface>
      </joint>
      <actuator name="motor_2">
        <hardwareInterface>PositionJointInterface</hardwareInterface>
        <mechanicalReduction>1</mechanicalReduction>
      </actuator>
    </transmission>
    <transmission name="tran_3">
      <robotNamespace>/conveyor</robotNamespace>
      <type>transmission_interface/SimpleTransmission</type>
      <joint name="third_joint">
        <hardwareInterface>PositionJointInterface</hardwareInterface>
      </joint>
      <actuator name="motor_3">
        <hardwareInterface>PositionJointInterface</hardwareInterface>
        <mechanicalReduction>1</mechanicalReduction>
      </actuator>
    </transmission>

    <transmission name="tran_4">
      <robotNamespace>/conveyor</robotNamespace>
      <type>transmission_interface/SimpleTransmission</type>
      <joint name="fourth_joint">
        <hardwareInterface>PositionJointInterface</hardwareInterface>
      </joint>
      <actuator name="motor_4">
        <hardwareInterface>PositionJointInterface</hardwareInterface>
        <mechanicalReduction>1</mechanicalReduction>
      </actuator>
    </transmission>    
    
    <transmission name="tran_5">
      <robotNamespace>/conveyor</robotNamespace>
      <type>transmission_interface/SimpleTransmission</type>
      <joint name="fifth_joint">
        <hardwareInterface>PositionJointInterface</hardwareInterface>
      </joint>
      <actuator name="motor_5">
        <hardwareInterface>PositionJointInterface</hardwareInterface>
        <mechanicalReduction>1</mechanicalReduction>
      </actuator>
    </transmission>

    <transmission name="tran_6">
      <robotNamespace>/conveyor</robotNamespace>
      <type>transmission_interface/SimpleTransmission</type>
      <joint name="seventh_joint">
        <hardwareInterface>PositionJointInterface</hardwareInterface>
      </joint>
      <actuator name="motor_6">
        <hardwareInterface>PositionJointInterface</hardwareInterface>
        <mechanicalReduction>1</mechanicalReduction>
      </actuator>
    </transmission>

    <transmission name="tran_7">
      <robotNamespace>/conveyor</robotNamespace>
      <type>transmission_interface/SimpleTransmission</type>
      <joint name="seventh_joint">
        <hardwareInterface>PositionJointInterface</hardwareInterface>
      </joint>
      <actuator name="motor_7">
        <hardwareInterface>PositionJointInterface</hardwareInterface>
        <mechanicalReduction>1</mechanicalReduction>
      </actuator>
    </transmission>

    <!-- <frame name='top_center'>
      <pose frame='world'>0 0 0.7645 0 -0 0</pose>
    </frame> -->
<!-- 
    <static>1</static>
    <allow_auto_disable>1</allow_auto_disable> -->
  </model>
</sdf>
