<?xml version="1.0"?>
<!-- =================================================================================== -->
<!-- |    This document was autogenerated by xacro from yaskawa7.urdf.xacro               | -->
<!-- |    EDITING THIS FILE BY HAND IS NOT RECOMMENDED                                 | -->
<!-- =================================================================================== -->
<robot name="conveyor_belt_dof2" xmlns:xacro="http://www.ros.org/wiki/xacro">
  <!-- Import Rviz colors -->


    <!-- LINKS -->
    <!-- virtual link interfacing with ee_mount on robot arm-->
    <link name="ee_base">
      <visual>
        <geometry>
          <box size="0.1 0.1 0.1"/>
        </geometry>
        <origin rpy="0 0 0" xyz="0 0 0"/>
      </visual>
    </link>

    <!-- links of cylinder base connected with the ee_base -->
    <link name="conveyor_belt_dof1_link">
      <visual>
        <material name="white">
          <color rgba="1.0 1.0 1.0 1.0"/>
        </material>
        <geometry>
          <mesh filename="../mesh/CBEE_v4_base_drake.obj" />
        </geometry>
        <origin rpy="0 0 0" xyz="0 0 0"/>
      </visual>
      <collision>
        <geometry>
          <mesh filename="../mesh/CBEE_v4_base_drake.obj" />
        </geometry>
        <origin rpy="0 0 0" xyz="0 0 0"/>
      </collision>
    </link>

    <!-- virtual link, equivlent of TCP (Tool Center Point) -->
    <link name="whisker_right_link">
      <visual>
        <geometry>
          <mesh filename="../mesh/CBEE_v4_whisker_drake.obj" />
        </geometry>
        <origin rpy="0 0 0" xyz="0 0 0"/>
      </visual>
      <collision>
        <geometry>
          <mesh filename="../mesh/CBEE_v4_whisker_drake.obj" />
        </geometry>
        <origin rpy="0 0 0" xyz="0 0 0"/>
      </collision>
    </link>

    <link name="whisker_left_link">
      <visual>
        <geometry>
          <mesh filename="../mesh/CBEE_v4_whisker_drake.obj" />
        </geometry>
        <origin rpy="0 0 0" xyz="0 0 0"/>
      </visual>
      <collision>
        <geometry>
          <mesh filename="../mesh/CBEE_v4_whisker_drake.obj" />
        </geometry>
        <origin rpy="0 0 0" xyz="0 0 0"/>
      </collision>
    </link>

    <!-- END LINKS -->

    <!-- JOINTS -->
    <!-- virtual joint, interfacing with arm -->
    <!-- <joint name="ee_base_joint" type="fixed">
      <parent link="ee_mount"/>
      <child link="ee_base"/>
      <origin xyz="0 0 0" rpy="0 0 0"/>
    </joint> -->

    <!-- virtual joint, connect ee_base to various link in end effector -->
    <joint name="conveyor_belt_dof1_joint" type="fixed">
      <parent link="ee_base"/>
      <child link="conveyor_belt_dof1_link"/>
      <origin xyz="0 0 0" rpy="0 0 0"/>
    </joint>

    <!-- virtual joint point to ee_tip_<number> (TCP) -->
    <joint name="whisker_right_joint" type="revolute">
      <parent link="conveyor_belt_dof1_link"/>
      <child link="whisker_right_link"/>
      <origin xyz="0.54 0 0" rpy="0 0 0"/>
    </joint>
    <!-- virtual joint point to ee_tip_<number> (TCP) -->
    <joint name="whisker_left_joint" type="revolute">
      <parent link="conveyor_belt_dof1_link"/>
      <child link="whisker_left_link"/>
      <origin xyz="0.54 0 0" rpy="0 0 0"/>
    </joint>
    <!-- END JOINTS -->

  <!--Extensions -->
  <!-- Load Gazebo lib and set the robot namespace -->
  <gazebo>
    <plugin filename="libgazebo_ros_control.so" name="gazebo_ros_controller">
      <robotNamespace>/yaskawa_ee</robotNamespace>
    </plugin>
  </gazebo>
  <!-- Link0 -->
  <gazebo reference="conveyor_belt_dof1_link">
    <material>Gazebo/Grey</material>
    <mu1>0.2</mu1>
    <mu2>0.2</mu2>
  </gazebo>
  <!-- Link0 -->
  <gazebo reference="whisker_right_link">
    <material>Gazebo/Grey</material>
    <mu1>0.2</mu1>
    <mu2>0.2</mu2>
  </gazebo>  
  <!-- Link0 -->
  <gazebo reference="whisker_left_link">
    <material>Gazebo/Grey</material>
    <mu1>0.2</mu1>
    <mu2>0.2</mu2>
  </gazebo>


 <transmission name="yaskawa_ee_1">
    <robotNamespace>/yaskawa</robotNamespace>
    <type>transmission_interface/SimpleTransmission</type>
    <joint name="whisker_right_joint">
      <hardwareInterface>PositionJointInterface</hardwareInterface>
    </joint>
    <actuator name="yaskawa_motor_1">
      <hardwareInterface>PositionJointInterface</hardwareInterface>
      <mechanicalReduction>1</mechanicalReduction>
    </actuator>
  </transmission>

  <transmission name="yaskawa_ee_2">
    <robotNamespace>/yaskawa</robotNamespace>
    <type>transmission_interface/SimpleTransmission</type>
    <joint name="whisker_left_joint">
      <hardwareInterface>PositionJointInterface</hardwareInterface>
    </joint>
    <actuator name="yaskawa_motor_2">
      <hardwareInterface>PositionJointInterface</hardwareInterface>
      <mechanicalReduction>1</mechanicalReduction>
    </actuator>
  </transmission>


  <!-- <transmission name="yaskawa_tran_1">
    <robotNamespace>/yaskawa</robotNamespace>
    <type>transmission_interface/SimpleTransmission</type>
    <joint name="ee_tip_0_joint">
      <hardwareInterface>PositionJointInterface</hardwareInterface>
    </joint>
    <actuator name="yaskawa_motor_1">
      <hardwareInterface>PositionJointInterface</hardwareInterface>
      <mechanicalReduction>1</mechanicalReduction>
    </actuator>
  </transmission> -->

</robot>

