<?xml version="1.0" encoding="utf-8"?>
<!-- This URDF was automatically created by SolidWorks to URDF Exporter! Originally created by Stephen Brawner (brawner@gmail.com) 
     Commit Version: 1.5.1-0-g916b5db  Build Version: 1.5.7152.31018
     For more information, please see http://wiki.ros.org/sw_urdf_exporter -->
<robot name="yaskawa" xmlns:xacro="http://www.ros.org/wiki/xacro">

  <material name="black">
    <color rgba="0.0 0.0 0.0 1.0"/>
  </material>
  <material name="blue">
    <color rgba="0 0 1.0 1.0"/>
  </material>

  <link name="arm_base"/>

  <link name="gp25_fixed_base_link">
    <visual>
      <material name="black"/>
      <geometry>
        <mesh filename = "../mesh/gp25_base_700.obj" />
        <!-- alternatively, it could be a box or cylinder -->
        <!-- <cylinder length="0.15" radius="0.025"/> -->
      </geometry>
      <origin rpy="0 0 0" xyz="0 0 0"/>
    </visual>
  </link>

  <link name="f_link">
    <inertial>
      <origin
        xyz="-0.031915 0.0021754 0.091588"
        rpy="0 0 0" />
      <mass
        value="9.3324" />
      <inertia
        ixx="0.1098"
        ixy="0.0028375"
        ixz="0.0065426"
        iyy="0.14811"
        iyz="-0.0011608"
        izz="0.22448" />
    </inertial>
    <visual>
      <origin
        xyz="0 0 0"
        rpy="0 0 0" />
      <geometry>
        <mesh
          filename="../meshes/base_link.obj" />
      </geometry>
      <material name="blue"/>
    </visual>
  </link>
  
  <link name="s_Link">
    <inertial>
      <origin
        xyz="-0.038076 0.20667 0.061766"
        rpy="0 0 0" />
      <mass
        value="15.959" />
      <inertia
        ixx="0.25529"
        ixy="0.017445"
        ixz="0.0061699"
        iyy="0.24074"
        iyz="-0.052601"
        izz="0.21792" />
    </inertial>
    <visual>
      <origin
        xyz="0 0 0"
        rpy="0 0 0" />
      <geometry>
        <mesh
          filename="../meshes/s_Link.obj" />
      </geometry>
      <material name="blue"/>
    </visual>
  </link>





  <link name="l_Link">
    <inertial>
      <origin
        xyz="-0.00062167 0.39609 0.0888"
        rpy="0 0 0" />
      <mass
        value="5.7076" />
      <inertia
        ixx="0.34116"
        ixy="0.0021389"
        ixz="-0.00023475"
        iyy="0.019361"
        iyz="0.011447"
        izz="0.35339" />
    </inertial>
    <visual>
      <origin
        xyz="0 0 0"
        rpy="0 0 0" />
      <geometry>
        <mesh
          filename="../meshes/l_Link.obj" />
      </geometry>
      <material name="blue"/>
    </visual>
  </link>
 
  <link name="u_Link">
    <inertial>
      <origin
        xyz="-0.09664 -0.036888 0.093881"
        rpy="0 0 0" />
      <mass
        value="7.4543" />
      <inertia
        ixx="0.053003"
        ixy="0.00038685"
        ixz="0.028037"
        iyy="0.087936"
        iyz="-0.0013279"
        izz="0.058106" />
    </inertial>
    <visual>
      <origin
        xyz="0 0 0"
        rpy="0 0 0" />
      <geometry>
        <mesh
          filename="../meshes/u_Link.obj" />
      </geometry>
      <material name="blue"/>
    </visual>
  </link>

 
  <link name="r_Link">
    <inertial>
      <origin
        xyz="0.29012 -0.00040394 0.025862"
        rpy="0 0 0" />
      <mass  value="4.0138" />
      <inertia
        ixx="0.013092"
        ixy="-0.00031733"
        ixz="0.002754"
        iyy="0.078287"
        iyz="-0.00036811"
        izz="0.076871" />
    </inertial>
    <visual>
      <origin
        xyz="0 0 0"
        rpy="0 0 0" />
      <geometry>
        <mesh filename="../meshes/r_Link.obj" />
      </geometry>
      <material name="blue"/>
    </visual>
  </link>


  <link
    name="b_Link">
    <inertial>
      <origin
        xyz="0.0238 0.018199 0.00056212"
        rpy="0 0 0" />
      <mass
        value="2.4338" />
      <inertia
        ixx="0.0042554"
        ixy="-1.3463E-05"
        ixz="4.7464E-07"
        iyy="0.0041237"
        iyz="5.7202E-05"
        izz="0.0042659" />
    </inertial>
    <visual>
      <origin
        xyz="0 0 0"
        rpy="0 0 0" />
      <geometry>
        <mesh
          filename="../meshes/b_Link.obj" />
      </geometry>
      <material name="blue"/>
    </visual>
  </link>
 
  <link
    name="t_Link">
    <inertial>
      <origin
        xyz="0.012736 -3.8333E-05 -1.8968E-09"
        rpy="0 0 0" />
      <mass
        value="0.61827" />
      <inertia
        ixx="0.0010925"
        ixy="1.2818E-07"
        ixz="3.4704E-09"
        iyy="0.00056974"
        iyz="-6.0117E-06"
        izz="0.00056044" />
    </inertial>
    <visual>
      <origin
        xyz="0 0 0"
        rpy="0 0 0" />
      <geometry>
        <mesh
          filename="../meshes/t_Link.obj" />
      </geometry>
      <material
        name="">
        <color
          rgba="0.83137 0.67059 0.12941 1" />
      </material>
    </visual>
  </link>


  <joint name="mh25_fixed_base_link_joint" type="fixed">
    <origin xyz="0 0 0" rpy="0 0 0"/>
    <parent link="arm_base"/>
    <child link="gp25_fixed_base_link"/>
  </joint>
  <joint name="f_joint" type="fixed">
    <origin xyz="0.0 0.0 0.71" rpy="-1.5708 0 0"/> <!-- FIX THIS: the height of the base is wrong-->
    <parent link="gp25_fixed_base_link"/>
    <child link="f_link"/>
  </joint>

  <joint name="s" type="revolute">
    <origin
      xyz="0 -0.15075 0"
      rpy="3.1416 -1.5708 0" />
    <parent
      link="f_link" />
    <child
      link="s_Link" />
    <axis
      xyz="0 1 0" />
  </joint>
  
  <joint name="l" type="revolute">
    <origin
      xyz="-0.062998 0.35425 0.15"
      rpy="0 -1.5708 0" />
    <parent
      link="s_Link" />
    <child
      link="l_Link" />
    <axis
      xyz="0 0 1" />
  </joint>

 <joint name="u" type="revolute">
    <origin
      xyz="0 0.76 0"
      rpy="1.5708 0 -3.1416" />
    <parent
      link="l_Link" />
    <child
      link="u_Link" />
    <axis
      xyz="0 1 0" />
  </joint>

  <joint name="r"
    type="revolute">
    <origin
      xyz="-0.22499 -0.062998 0.2"
      rpy="0 0 3.1416" />
    <parent
      link="u_Link" />
    <child
      link="r_Link" />
    <axis
      xyz="1 0 0" />
  </joint>

 <joint name="b"
    type="revolute">
    <origin
      xyz="0.57001 0 0"
      rpy="3.1416 0 0" />
    <parent
      link="r_Link" />
    <child
      link="b_Link" />
    <axis
      xyz="0 1 0" />
  </joint>

  <joint name="t"
    type="revolute">
    <origin
      xyz="0.074491 0 0"
      rpy="-1.5708 0 0" />
    <parent
      link="b_Link" />
    <child
      link="t_Link" />
    <axis
      xyz="1 0 0" />
  </joint>


  <gazebo>
    <plugin filename="libgazebo_ros_control.so" name="gazebo_ros_controller">
      <robotNamespace>/yaskawa</robotNamespace>
    </plugin>
  </gazebo>
  <!-- Link0 -->
  <gazebo reference="arm_base">
    <material>Gazebo/Grey</material>
    <mu1>0.2</mu1>
    <mu2>0.2</mu2>
  </gazebo>
  <!-- Link0 -->
  <gazebo reference="f_Link">
    <material>Gazebo/Grey</material>
    <mu1>0.2</mu1>
    <mu2>0.2</mu2>
  </gazebo>  
  <!-- Link0 -->
  <gazebo reference="s_Link">
    <material>Gazebo/Grey</material>
    <mu1>0.2</mu1>
    <mu2>0.2</mu2>
  </gazebo>  
  <!-- Link0 -->
  <gazebo reference="l_Link">
    <material>Gazebo/Grey</material>
    <mu1>0.2</mu1>
    <mu2>0.2</mu2>
  </gazebo>  
  <!-- Link0 -->
  <gazebo reference="u_Link">
    <material>Gazebo/Grey</material>
    <mu1>0.2</mu1>
    <mu2>0.2</mu2>
  </gazebo>  
  <!-- Link0 -->
  <gazebo reference="r_Link">
    <material>Gazebo/Grey</material>
    <mu1>0.2</mu1>
    <mu2>0.2</mu2>
  </gazebo>
   <!-- Link0 -->
  <gazebo reference="b_Link">
    <material>Gazebo/Grey</material>
    <mu1>0.2</mu1>
    <mu2>0.2</mu2>
  </gazebo>
   <!-- Link0 -->
  <gazebo reference="t_Link">
    <material>Gazebo/Grey</material>
    <mu1>0.2</mu1>
    <mu2>0.2</mu2>
  </gazebo>
   <!-- Link0 -->
  <!-- <gazebo reference="ee_mount">
    <material>Gazebo/Grey</material>
    <mu1>0.2</mu1>
    <mu2>0.2</mu2>
  </gazebo> -->


  <transmission name="yaskawa_tran_1">
    <robotNamespace>/yaskawa</robotNamespace>
    <type>transmission_interface/SimpleTransmission</type>
    <joint name="s">
      <hardwareInterface>PositionJointInterface</hardwareInterface>
    </joint>
    <actuator name="yaskawa_motor_1">
      <hardwareInterface>PositionJointInterface</hardwareInterface>
      <mechanicalReduction>1</mechanicalReduction>
    </actuator>
  </transmission>

  <transmission name="yaskawa_tran_2">
    <robotNamespace>/yaskawa</robotNamespace>
    <type>transmission_interface/SimpleTransmission</type>
    <joint name="l">
      <hardwareInterface>PositionJointInterface</hardwareInterface>
    </joint>
    <actuator name="yaskawa_motor_2">
      <hardwareInterface>PositionJointInterface</hardwareInterface>
      <mechanicalReduction>1</mechanicalReduction>
    </actuator>
  </transmission>

  <transmission name="yaskawa_tran_3">
    <robotNamespace>/yaskawa</robotNamespace>
    <type>transmission_interface/SimpleTransmission</type>
    <joint name="u">
      <hardwareInterface>PositionJointInterface</hardwareInterface>
    </joint>
    <actuator name="yaskawa_motor_3">
      <hardwareInterface>PositionJointInterface</hardwareInterface>
      <mechanicalReduction>1</mechanicalReduction>
    </actuator>
  </transmission>

  <transmission name="yaskawa_tran_4">
    <robotNamespace>/yaskawa</robotNamespace>
    <type>transmission_interface/SimpleTransmission</type>
    <joint name="r">
      <hardwareInterface>PositionJointInterface</hardwareInterface>
    </joint>
    <actuator name="yaskawa_motor_4">
      <hardwareInterface>PositionJointInterface</hardwareInterface>
      <mechanicalReduction>1</mechanicalReduction>
    </actuator>
  </transmission>

  <transmission name="yaskawa_tran_5">
    <robotNamespace>/yaskawa</robotNamespace>
    <type>transmission_interface/SimpleTransmission</type>
    <joint name="b">
      <hardwareInterface>PositionJointInterface</hardwareInterface>
    </joint>
    <actuator name="yaskawa_motor_5">
      <hardwareInterface>PositionJointInterface</hardwareInterface>
      <mechanicalReduction>1</mechanicalReduction>
    </actuator>
  </transmission>

  <transmission name="yaskawa_tran_6">
    <robotNamespace>/yaskawa</robotNamespace>
    <type>transmission_interface/SimpleTransmission</type>
    <joint name="t">
      <hardwareInterface>PositionJointInterface</hardwareInterface>
    </joint>
    <actuator name="yaskawa_motor_6">
      <hardwareInterface>PositionJointInterface</hardwareInterface>
      <mechanicalReduction>1</mechanicalReduction>
    </actuator>
  </transmission>





</robot>