temp yaskawa urdf
<?xml version="1.0" ?>
<!-- =================================================================================== -->
<!-- |    This document was autogenerated by xacro from iiwa7.urdf.xacro               | -->
<!-- |    EDITING THIS FILE BY HAND IS NOT RECOMMENDED                                 | -->
<!-- =================================================================================== -->
<robot name="yaskawa" xmlns:xacro="http://www.ros.org/wiki/xacro">
  <!-- Import Rviz colors -->

    <material name="blue">
      <color rgba="0 0 1.0 1.0"/>
    </material>
    <material name="black">
      <color rgba="0.0 0.0 0.0 1.0"/>
    </material>

<!-- LINKS -->
    <!-- virtual link for interfacing with base-->
    <link name="arm_base">
      <visual>
        <geometry>
          <box size="0.1 0.1 0.1"/>
        </geometry>
        <origin rpy="0 0 0" xyz="0 0 0"/>
      </visual>
    </link>

    <!-- This link could be way more complicated if it's a mobile base, especially legged base   gp25_fixed_base_link-->
    <link name="gp25_fixed_base_link">
      <visual>
        <material name="black"/>
        <geometry>
          <mesh filename = "../mesh/gp25_base_700.obj" />
          <!-- alternatively, it could be a box or cylinder -->
          <!-- <cylinder length="0.15" radius="0.025"/> -->
        </geometry>
        <origin rpy="0 0 0" xyz="0 0 0"/>
      </visual>
    </link>
    <!-- Foundation, link 0, sometimes referred to as base_link-->
    <link name="f_link">
      <visual>
        <origin xyz="0 0 0" rpy="0 0 0"/>
        <geometry>
          <mesh filename="../mesh/f-visual.obj" scale="1 1 1"/>
        </geometry>
        <material name="blue"/>
      </visual>
    </link>
    <!-- Swing/Swivel , link 1 (A1) -->
    <link name="s_link">
      <visual>
        <origin xyz="0 0 0" rpy="0 0 0"/>
        <geometry>
          <mesh filename="../mesh/s-visual.obj" scale="1 1 1"/>
        </geometry>
        <material name="blue"/>
      </visual>
    </link>
    <!-- Lower arm, link 2 -->
    <link name="l_link">
      <visual>
        <origin xyz="0 0 0" rpy="0 0 0"/>
        <geometry>
          <mesh filename="../mesh/l-visual.obj" scale="1 1 1"/>
        </geometry>
        <material name="blue"/>
      </visual>
    </link>
    <!-- Upper arm, link 3 -->
    <link name="u_link">
      <visual>
        <origin xyz="0 0 0" rpy="0 0 0"/>
        <geometry>
          <mesh filename="../mesh/u-visual.obj" scale="1 1 1"/>
        </geometry>
        <material name="blue"/>
      </visual>
    </link>
    <!-- arm Roll/wrist Rotation, link 4  -->
    <link name="r_link">
      <visual>
        <origin xyz="0 0 0" rpy="0 0 0"/>
        <geometry>
          <mesh filename="../mesh/r-visual.obj" scale="1 1 1"/>
        </geometry>
        <material name="blue"/>
      </visual>
    </link>
    <!-- wrist Bend, link 5 -->
    <link name="b_link">
      <visual>
        <origin xyz="0 0 0" rpy="0 0 0"/>
        <geometry>
          <mesh filename="../mesh/b-visual.obj" scale="1 1 1"/>
        </geometry>
        <material name="blue"/>
      </visual>
    </link>
    <!-- Tool flange/wrist Turning, link 6 -->
    <link name="t_link">
      <visual>
        <origin xyz="0 0 0" rpy="0 0 0"/>
        <geometry>
          <mesh filename="../mesh/t-visual.obj" scale="1 1 1"/>
        </geometry>
        <material name="blue"/>
      </visual>
    </link>
    <!-- virtual link for interfacing with end effector-->
    <link name="ee_mount">
      <visual>
        <geometry>
          <box size="0.01 0.01 0.01"/>
        </geometry>
        <origin rpy="0 0 0" xyz="0 0 0"/>
      </visual>
    </link>
    <!-- END LINKS -->

    <!-- JOINTS -->
    <!-- virtual joint -->
    <!-- virtual joint for interfacing with base -->
    <!-- <joint name="arm_base_joint" type="fixed">
      <parent link="arm_mount"/>
      <child link="arm_base"/>
      <origin xyz="0.0 0.0 0.0" rpy="0 0 0"/>
    </joint> -->

    <!-- JOINTS -->
    <!-- virtual joint, connect fixed_base_footprint to various link in base -->
    <joint name="mh25_fixed_base_link_joint" type="fixed">
      <origin xyz="0 0 0" rpy="0 0 0"/>
      <parent link="arm_base"/>
      <child link="gp25_fixed_base_link"/>
    </joint>
    <!-- virtual joint -->
    <joint name="f_joint" type="fixed">
      <origin xyz="0.0 0.0 0.7" rpy="0 0 0"/>
      <parent link="gp25_fixed_base_link"/>
      <child link="f_link"/>
    </joint>
    <!-- joint 1 (A1) -->
    <joint name="s_joint" type="revolute">
      <origin xyz="0 0 0.169" rpy="0 0 0"/>
      <parent link="f_link"/>
      <child link="s_link"/>
      <axis xyz="0 0 1"/>
      <!-- <limit effort="0" lower="3.14159" upper="3.14159" velocity="3.66519"/> -->
    </joint>
    <!-- joint 2 (A2) -->
    <joint name="l_joint" type="revolute">
      <origin xyz="0.150 -0.112 0.336" rpy="0 0 0"/>
      <parent link="s_link"/>
      <child link="l_link"/>
      <axis xyz="0 1 0"/>
      <!-- <limit effort="0" lower="1.8326" upper="2.70526" velocity="3.66519"/> -->
    </joint>
    <!-- joint 3 (A3) -->
    <joint name="u_joint" type="revolute">
      <origin xyz="0 0.049 0.760" rpy="0 0 0"/>
      <parent link="l_link"/>
      <child link="u_link"/>
      <axis xyz="0 -1 0"/>
      <!-- <limit effort="0" lower="1.50098" upper="2.79253" velocity="4.62512"/> -->
    </joint>
    <!-- joint 4 (A4) -->
    <joint name="r_joint" type="revolute">
      <origin xyz="0.295 0.066 0.200" rpy="0 0 0"/>
      <parent link="u_link"/>
      <child link="r_link"/>
      <axis xyz="-1 0 0"/>
      <!-- <limit effort="0" lower="3.49066" upper="3.49066" velocity="7.33038"/> -->
    </joint>
    <!-- joint 5 (A5) -->
    <joint name="b_joint" type="revolute">
      <origin xyz="0.500 -0.063 0.0" rpy="0 0 0"/>
      <parent link="r_link"/>
      <child link="b_link"/>
      <axis xyz="0 -1 0"/>
      <!-- <limit effort="0" lower="2.61799" upper="2.61799" velocity="7.33038"/> -->
    </joint>
    <!-- joint 6 (A6) -->
    <joint name="t_joint" type="revolute">
      <origin xyz="0.100 0.060 0.0" rpy="0 0 0"/>
      <parent link="b_link"/>
      <child link="t_link"/>
      <axis xyz="-1 0 0"/>
      <!-- <limit effort="0" lower="7.94125" upper="7.94125" velocity="15.4462"/> -->
    </joint>
   <!-- virtual joint for interfacing with end effector -->
    <joint name="ee_mount_joint" type="fixed">
      <parent link="t_link"/>
      <child link="ee_mount"/>
      <origin xyz="0.0 0.0 0.0" rpy="0 0 0"/>
    </joint>
    <!-- END JOINTS -->


  <!--Extensions -->
  <!-- Load Gazebo lib and set the robot namespace -->
  <gazebo>
    <plugin filename="libgazebo_ros_control.so" name="gazebo_ros_controller">
      <robotNamespace>/yaskawa</robotNamespace>
    </plugin>
  </gazebo>
  <!-- Link0 -->
  <gazebo reference="arm_base">
    <material>Gazebo/Grey</material>
    <mu1>0.2</mu1>
    <mu2>0.2</mu2>
  </gazebo>
  <!-- Link0 -->
  <gazebo reference="f_link">
    <material>Gazebo/Grey</material>
    <mu1>0.2</mu1>
    <mu2>0.2</mu2>
  </gazebo>  
  <!-- Link0 -->
  <gazebo reference="s_link">
    <material>Gazebo/Grey</material>
    <mu1>0.2</mu1>
    <mu2>0.2</mu2>
  </gazebo>  
  <!-- Link0 -->
  <gazebo reference="l_link">
    <material>Gazebo/Grey</material>
    <mu1>0.2</mu1>
    <mu2>0.2</mu2>
  </gazebo>  
  <!-- Link0 -->
  <gazebo reference="u_link">
    <material>Gazebo/Grey</material>
    <mu1>0.2</mu1>
    <mu2>0.2</mu2>
  </gazebo>  
  <!-- Link0 -->
  <gazebo reference="r_link">
    <material>Gazebo/Grey</material>
    <mu1>0.2</mu1>
    <mu2>0.2</mu2>
  </gazebo>
   <!-- Link0 -->
  <gazebo reference="b_link">
    <material>Gazebo/Grey</material>
    <mu1>0.2</mu1>
    <mu2>0.2</mu2>
  </gazebo>
   <!-- Link0 -->
  <gazebo reference="t_link">
    <material>Gazebo/Grey</material>
    <mu1>0.2</mu1>
    <mu2>0.2</mu2>
  </gazebo>
   <!-- Link0 -->
  <gazebo reference="ee_mount">
    <material>Gazebo/Grey</material>
    <mu1>0.2</mu1>
    <mu2>0.2</mu2>
  </gazebo>

  <transmission name="yaskawa_tran_1">
    <robotNamespace>/yaskawa</robotNamespace>
    <type>transmission_interface/SimpleTransmission</type>
    <joint name="s_joint">
      <hardwareInterface>PositionJointInterface</hardwareInterface>
    </joint>
    <actuator name="yaskawa_motor_1">
      <hardwareInterface>PositionJointInterface</hardwareInterface>
      <mechanicalReduction>1</mechanicalReduction>
    </actuator>
  </transmission>

  <transmission name="yaskawa_tran_2">
    <robotNamespace>/yaskawa</robotNamespace>
    <type>transmission_interface/SimpleTransmission</type>
    <joint name="l_joint">
      <hardwareInterface>PositionJointInterface</hardwareInterface>
    </joint>
    <actuator name="yaskawa_motor_2">
      <hardwareInterface>PositionJointInterface</hardwareInterface>
      <mechanicalReduction>1</mechanicalReduction>
    </actuator>
  </transmission>

  <transmission name="yaskawa_tran_3">
    <robotNamespace>/yaskawa</robotNamespace>
    <type>transmission_interface/SimpleTransmission</type>
    <joint name="u_joint">
      <hardwareInterface>PositionJointInterface</hardwareInterface>
    </joint>
    <actuator name="yaskawa_motor_3">
      <hardwareInterface>PositionJointInterface</hardwareInterface>
      <mechanicalReduction>1</mechanicalReduction>
    </actuator>
  </transmission>

  <transmission name="yaskawa_tran_4">
    <robotNamespace>/yaskawa</robotNamespace>
    <type>transmission_interface/SimpleTransmission</type>
    <joint name="r_joint">
      <hardwareInterface>PositionJointInterface</hardwareInterface>
    </joint>
    <actuator name="yaskawa_motor_4">
      <hardwareInterface>PositionJointInterface</hardwareInterface>
      <mechanicalReduction>1</mechanicalReduction>
    </actuator>
  </transmission>

  <transmission name="yaskawa_tran_5">
    <robotNamespace>/yaskawa</robotNamespace>
    <type>transmission_interface/SimpleTransmission</type>
    <joint name="b_joint">
      <hardwareInterface>PositionJointInterface</hardwareInterface>
    </joint>
    <actuator name="yaskawa_motor_5">
      <hardwareInterface>PositionJointInterface</hardwareInterface>
      <mechanicalReduction>1</mechanicalReduction>
    </actuator>
  </transmission>

  <transmission name="yaskawa_tran_6">
    <robotNamespace>/yaskawa</robotNamespace>
    <type>transmission_interface/SimpleTransmission</type>
    <joint name="t_joint">
      <hardwareInterface>PositionJointInterface</hardwareInterface>
    </joint>
    <actuator name="yaskawa_motor_6">
      <hardwareInterface>PositionJointInterface</hardwareInterface>
      <mechanicalReduction>1</mechanicalReduction>
    </actuator>
  </transmission>
</robot>
