<?xml version="1.0" ?>
<!-- =================================================================================== -->
<!-- |    This document was autogenerated by xacro from iiwa7.urdf.xacro               | -->
<!-- |    EDITING THIS FILE BY HAND IS NOT RECOMMENDED                                 | -->
<!-- =================================================================================== -->
<robot name="yaskawa" xmlns:xacro="http://www.ros.org/wiki/xacro">
  <!-- Import Rviz colors -->

    <material name="blue">
      <color rgba="0 0 1.0 1.0"/>
    </material>
    <material name="black">
      <color rgba="0.0 0.0 0.0 1.0"/>
    </material>
      <material name="red">
      <color rgba="1.0 0.0 0.0 1.0"/>
    </material>
    <material name="yellow">
      <color rgba="0.0 1.0 1.0 1.0"/>
    </material>
    <material name="green">
      <color rgba="0.0 1.0 0.0 1.0"/>
    </material>

<!-- LINKS -->
    <!-- virtual link for interfacing with base-->
    <link name="arm_base"/>

    <!-- This link could be way more complicated if it's a mobile base, especially legged base   gp25_fixed_base_link-->
    <link name="gp25_fixed_base_link">
      <visual>
        <material name="black"/>
        <geometry>
          <mesh filename = "../mesh/gp25_base_700.obj" />
          <!-- alternatively, it could be a box or cylinder -->
          <!-- <cylinder length="0.15" radius="0.025"/> -->
        </geometry>
        <origin rpy="0 0 0" xyz="0 0 0"/>
      </visual>
    </link>
    <!-- Foundation, link 0, sometimes referred to as base_link-->
    <link name="f_link">
      <inertial>
        <origin
          xyz="-0.031915 0.0021754 0.091588"
          rpy="0 0 0" />
        <mass
          value="9.3324" />
        <inertia
          ixx="0.1098"
          ixy="0.0028375"
          ixz="0.0065426"
          iyy="0.14811"
          iyz="-0.0011608"
          izz="0.22448" />
      </inertial>
      <visual>
        <origin xyz="0 0 0" rpy="0 0 0"/>
        <geometry>
          <mesh filename="../mesh/f-visual.obj" scale="1 1 1"/>
        </geometry>
        <material name="blue"/>
      </visual>
    </link>
    <!-- Swing/Swivel , link 1 (A1) -->
    <link name="s_link">
      <inertial>
        <origin
          xyz="-0.038076 0.20667 0.061766"
          rpy="0 0 0" />
        <mass
          value="15.959" />
        <inertia
          ixx="0.25529"
          ixy="0.017445"
          ixz="0.0061699"
          iyy="0.24074"
          iyz="-0.052601"
          izz="0.21792" />
      </inertial>
      <visual>
        <origin xyz="0 0 0" rpy="0 0 0"/>
        <geometry>
          <mesh filename="../mesh/s-visual.obj" scale="1 1 1"/>
        </geometry>
        <material name="blue"/>
      </visual>
    </link>
    <!-- Lower arm, link 2 -->
    <link name="l_link">
      <inertial>
        <origin
          xyz="-0.00062167 0.39609 0.0888"
          rpy="0 0 0" />
        <mass
          value="5.7076" />
        <inertia
          ixx="0.34116"
          ixy="0.0021389"
          ixz="-0.00023475"
          iyy="0.019361"
          iyz="0.011447"
          izz="0.35339" />
      </inertial>
      <visual>
        <origin xyz="0 0 0" rpy="0 0 0"/>
        <geometry>
          <mesh filename="../mesh/l-visual.obj" scale="1 1 1"/>
        </geometry>
        <material name="blue"/>
      </visual>
    </link>
    <!-- Upper arm, link 3 -->
    <link name="u_link">
      <inertial>
        <origin
          xyz="-0.09664 -0.036888 0.093881"
          rpy="0 0 0" />
        <mass
          value="7.4543" />
        <inertia
          ixx="0.053003"
          ixy="0.00038685"
          ixz="0.028037"
          iyy="0.087936"
          iyz="-0.0013279"
          izz="0.058106" />
      </inertial>
      <visual>
        <origin xyz="0 0 0" rpy="0 0 0"/>
        <geometry>
          <mesh filename="../mesh/u-visual.obj" scale="1 1 1"/>
        </geometry>
        <material name="blue"/>
      </visual>
    </link>
    <!-- arm Roll/wrist Rotation, link 4  -->
    <link name="r_link">
    <inertial>
        <origin
          xyz="0.29012 -0.00040394 0.025862"
          rpy="0 0 0" />
        <mass  value="4.0138" />
        <inertia
          ixx="0.013092"
          ixy="-0.00031733"
          ixz="0.002754"
          iyy="0.078287"
          iyz="-0.00036811"
          izz="0.076871" />
      </inertial>
      <visual>
        <origin xyz="0 0 0" rpy="0 0 0"/>
        <geometry>
          <mesh filename="../mesh/r-visual.obj" scale="1 1 1"/>
        </geometry>
        <material name="blue"/>
      </visual>
    </link>
    <!-- wrist Bend, link 5 -->
    <link name="b_link">
      <inertial>
        <origin
          xyz="0.0238 0.018199 0.00056212"
          rpy="0 0 0" />
        <mass
          value="2.4338" />
        <inertia
          ixx="0.0042554"
          ixy="-1.3463E-05"
          ixz="4.7464E-07"
          iyy="0.0041237"
          iyz="5.7202E-05"
          izz="0.0042659" />
      </inertial>
      <visual>
        <origin xyz="0 0.063 0" rpy="3.141592 0 0"/>
        <!-- <origin xyz="0 0 0" rpy="0 0 0"/> -->
        <geometry>
          <mesh filename="../mesh/b-visual2.obj" scale="1 1 1"/>
        </geometry>
        <material name="blue"/>
      </visual>
    </link>
    <!-- Tool flange/wrist Turning, link 6 -->
    <link name="t_link">
      <inertial>
        <origin
          xyz="0.012736 -3.8333E-05 -1.8968E-09"
          rpy="0 0 0" />
        <mass
          value="0.61827" />
        <inertia
          ixx="0.0010925"
          ixy="1.2818E-07"
          ixz="3.4704E-09"
          iyy="0.00056974"
          iyz="-6.0117E-06"
          izz="0.00056044" />
      </inertial>
      <visual>
        <!-- <origin xyz="-0.09 0 0" rpy="0 0 0"/> -->
        <origin xyz="0 0 0" rpy="0 0 0"/>
        <geometry>
          <mesh filename="../mesh/t-visual.obj" scale="1 1 1"/>
        </geometry>
        <material name="blue"/>
      </visual>
    </link>
    <!-- virtual link for interfacing with end effector-->
    <link name="ee_mount"/>
    <frame link="ee_mount" name="yaskawa_frame_ee" rpy="0 0 0" xyz="0.09 0 0"/>

    <!-- END LINKS -->

    <!-- JOINTS -->
    <!-- virtual joint -->
    <!-- virtual joint for interfacing with base -->
    <!-- <joint name="arm_base_joint" type="fixed">
      <parent link="arm_mount"/>
      <child link="arm_base"/>
      <origin xyz="0.0 0.0 0.0" rpy="0 0 0"/>
    </joint> -->

    <!-- JOINTS -->
    <!-- virtual joint, connect fixed_base_footprint to various link in base -->
    <joint name="mh25_fixed_base_link_joint" type="fixed">
      <origin xyz="0 0 0" rpy="0 0 0"/>
      <parent link="arm_base"/>
      <child link="gp25_fixed_base_link"/>
    </joint>
    <!-- virtual joint -->
    <joint name="f_joint" type="fixed">
      <origin xyz="0.0 0.0 0.71" rpy="0 0 0"/> <!-- FIX THIS: the height of the base is wrong-->
      <parent link="gp25_fixed_base_link"/>
      <child link="f_link"/>
    </joint>
    <!-- joint 1 (A1) -->
    <joint name="s_joint" type="revolute">
      <origin xyz="0 0 0.169" rpy="0 0 0"/>
      <parent link="f_link"/>
      <child link="s_link"/>
      <axis xyz="0 0 1"/>
      <!-- <limit effort="0" lower="3.14159" upper="3.14159" velocity="3.66519"/> -->
    </joint>
    <!-- joint 2 (A2) -->
    <joint name="l_joint" type="revolute">
      <parent link="s_link"/>
      <child link="l_link"/>
      <origin xyz="0.150 -0.112 0.336" rpy="0 0 0"/> <!-- TODO: Fix this value-->
      <axis xyz="0 1 0"/>
      <!-- <limit effort="0" lower="1.8326" upper="2.70526" velocity="3.66519"/> -->
    </joint>
    <!-- joint 3 (A3) -->
    <joint name="u_joint" type="revolute">
      <origin xyz="0 0.049 0.760" rpy="0 0 0"/>
      <parent link="l_link"/>
      <child link="u_link"/>
      <axis xyz="0 -1 0"/>
      <!-- <limit effort="0" lower="1.50098" upper="2.79253" velocity="4.62512"/> -->
    </joint>
    <!-- joint 4 (A4) -->
    <joint name="r_joint" type="revolute">
      <origin xyz="0.295 0.066 0.200" rpy="0 0 0"/>
      <parent link="u_link"/>
      <child link="r_link"/>
      <axis xyz="-1 0 0"/>
      <!-- <limit effort="0" lower="3.49066" upper="3.49066" velocity="7.33038"/> -->
    </joint>
    <!-- joint 5 (A5) -->
    <joint name="b_joint" type="revolute">
      <origin xyz="0.500 -0.063 0.0" rpy="0 0 0"/>
      <parent link="r_link"/>
      <child link="b_link"/>
      <axis xyz="0 -1 0"/>
      <!-- <limit effort="0" lower="2.61799" upper="2.61799" velocity="7.33038"/> -->
    </joint>
    <!-- joint 6 (A6) -->
    <joint name="t_joint" type="revolute">
      <origin xyz="0.100 0.060 0.0" rpy="0 0 0"/>
      <parent link="b_link"/>
      <child link="t_link"/>
      <axis xyz="-1 0 0"/>
      <!-- <limit effort="0" lower="7.94125" upper="7.94125" velocity="15.4462"/> -->
    </joint>
    <!-- virtual joint for interfacing with end effector -->
    <joint name="ee_mount_joint" type="fixed">
      <parent link="t_link"/>
      <child link="ee_mount"/>
      <origin xyz="0.0 0.0 0.0" rpy="0 0 0"/>
    </joint>
    <!-- END JOINTS -->


  <!--Extensions -->
  <!-- Load Gazebo lib and set the robot namespace -->
  <gazebo>
    <plugin filename="libgazebo_ros_control.so" name="gazebo_ros_controller">
      <robotNamespace>/yaskawa</robotNamespace>
    </plugin>
  </gazebo>
  <!-- Link0 -->
  <gazebo reference="arm_base">
    <material>Gazebo/Grey</material>
    <mu1>0.2</mu1>
    <mu2>0.2</mu2>
  </gazebo>
  <!-- Link0 -->
  <gazebo reference="f_link">
    <material>Gazebo/Grey</material>
    <mu1>0.2</mu1>
    <mu2>0.2</mu2>
  </gazebo>  
  <!-- Link0 -->
  <gazebo reference="s_link">
    <material>Gazebo/Grey</material>
    <mu1>0.2</mu1>
    <mu2>0.2</mu2>
  </gazebo>  
  <!-- Link0 -->
  <gazebo reference="l_link">
    <material>Gazebo/Grey</material>
    <mu1>0.2</mu1>
    <mu2>0.2</mu2>
  </gazebo>  
  <!-- Link0 -->
  <gazebo reference="u_link">
    <material>Gazebo/Grey</material>
    <mu1>0.2</mu1>
    <mu2>0.2</mu2>
  </gazebo>  
  <!-- Link0 -->
  <gazebo reference="r_link">
    <material>Gazebo/Grey</material>
    <mu1>0.2</mu1>
    <mu2>0.2</mu2>
  </gazebo>
   <!-- Link0 -->
  <gazebo reference="b_link">
    <material>Gazebo/Grey</material>
    <mu1>0.2</mu1>
    <mu2>0.2</mu2>
  </gazebo>
   <!-- Link0 -->
  <gazebo reference="t_link">
    <material>Gazebo/Grey</material>
    <mu1>0.2</mu1>
    <mu2>0.2</mu2>
  </gazebo>
   <!-- Link0 -->
  <!-- <gazebo reference="ee_mount">
    <material>Gazebo/Grey</material>
    <mu1>0.2</mu1>
    <mu2>0.2</mu2>
  </gazebo> -->


  <transmission name="yaskawa_tran_1">
    <robotNamespace>/yaskawa</robotNamespace>
    <type>transmission_interface/SimpleTransmission</type>
    <joint name="s_joint">
      <hardwareInterface>PositionJointInterface</hardwareInterface>
    </joint>
    <actuator name="yaskawa_motor_1">
      <hardwareInterface>PositionJointInterface</hardwareInterface>
      <mechanicalReduction>1</mechanicalReduction>
    </actuator>
  </transmission>

  <transmission name="yaskawa_tran_2">
    <robotNamespace>/yaskawa</robotNamespace>
    <type>transmission_interface/SimpleTransmission</type>
    <joint name="l_joint">
      <hardwareInterface>PositionJointInterface</hardwareInterface>
    </joint>
    <actuator name="yaskawa_motor_2">
      <hardwareInterface>PositionJointInterface</hardwareInterface>
      <mechanicalReduction>1</mechanicalReduction>
    </actuator>
  </transmission>

  <transmission name="yaskawa_tran_3">
    <robotNamespace>/yaskawa</robotNamespace>
    <type>transmission_interface/SimpleTransmission</type>
    <joint name="u_joint">
      <hardwareInterface>PositionJointInterface</hardwareInterface>
    </joint>
    <actuator name="yaskawa_motor_3">
      <hardwareInterface>PositionJointInterface</hardwareInterface>
      <mechanicalReduction>1</mechanicalReduction>
    </actuator>
  </transmission>

  <transmission name="yaskawa_tran_4">
    <robotNamespace>/yaskawa</robotNamespace>
    <type>transmission_interface/SimpleTransmission</type>
    <joint name="r_joint">
      <hardwareInterface>PositionJointInterface</hardwareInterface>
    </joint>
    <actuator name="yaskawa_motor_4">
      <hardwareInterface>PositionJointInterface</hardwareInterface>
      <mechanicalReduction>1</mechanicalReduction>
    </actuator>
  </transmission>

  <transmission name="yaskawa_tran_5">
    <robotNamespace>/yaskawa</robotNamespace>
    <type>transmission_interface/SimpleTransmission</type>
    <joint name="b_joint">
      <hardwareInterface>PositionJointInterface</hardwareInterface>
    </joint>
    <actuator name="yaskawa_motor_5">
      <hardwareInterface>PositionJointInterface</hardwareInterface>
      <mechanicalReduction>1</mechanicalReduction>
    </actuator>
  </transmission>

  <transmission name="yaskawa_tran_6">
    <robotNamespace>/yaskawa</robotNamespace>
    <type>transmission_interface/SimpleTransmission</type>
    <joint name="t_joint">
      <hardwareInterface>PositionJointInterface</hardwareInterface>
    </joint>
    <actuator name="yaskawa_motor_6">
      <hardwareInterface>PositionJointInterface</hardwareInterface>
      <mechanicalReduction>1</mechanicalReduction>
    </actuator>
  </transmission>

</robot>
