<?xml version="1.0"?>
<!-- =================================================================================== -->
<!-- |    This document was autogenerated by xacro from yaskawa7.urdf.xacro               | -->
<!-- |    EDITING THIS FILE BY HAND IS NOT RECOMMENDED                                 | -->
<!-- =================================================================================== -->
<robot name="conveyor_belt_dof1" xmlns:xacro="http://www.ros.org/wiki/xacro">
  <!-- Import Rviz colors -->
    <material name="green">
      <color rgba="0.0 1.0 0.0 1.0"/>
    </material>
    <material name="blue">
      <color rgba="0.0 0.0 1.0 1.0"/>
    </material>
    <material name="red">
      <color rgba="1.0 0.0 0.0 1.0"/>
    </material>
    <material name="white">
      <color rgba="1.0 1.0 1.0 1.0"/>
    </material>


    <!-- LINKS -->
    <!-- virtual link interfacing with ee_mount on robot arm-->
    <link name="ee_base">
      <visual>
        <geometry>
          <!-- <mesh filename="../mesh/cbee_gripper_1st-collision.obj" /> -->
          <box size="0.01 0.01 0.01"/>
        </geometry>
        <!-- <origin rpy="0 0 3.14" xyz="0.55 0 -0.2"/> -->
      </visual>
    </link>

    <link name="cover_back">
      <inertial>
        <mass value="0.001"/>
        <inertia ixx="0.1" ixy="0.0" ixz="0.0" iyy="0.1" iyz="0.0" izz="0.1"/>
      </inertial>
      <visual>
        <material name="white"/>
        <origin xyz="0 0 0" rpy="0 0 0"/>
        <geometry>
          <box size="0.01 0.35 0.05"/>
        </geometry>
      </visual>
      <collision>
        <geometry>
          <box size="0.01 0.35 0.05"/>
        </geometry>
      </collision>
    </link>

    <link name="cover_left">
      <inertial>
        <mass value="0.001"/>
        <inertia ixx="0.1" ixy="0.0" ixz="0.0" iyy="0.1" iyz="0.0" izz="0.1"/>
      </inertial>
      <visual>
        <material name="white"/>
        <origin xyz="0 0 0" rpy="0 0 0"/>
        <geometry>
          <box size="0.01 0.35 0.05"/>
        </geometry>
      </visual>
      <collision>
        <geometry>
          <box size="0.01 0.35 0.05"/>
        </geometry>
      </collision>
    </link>

    <link name="cover_right">
      <inertial>
        <mass value="0.001"/>
        <inertia ixx="0.1" ixy="0.0" ixz="0.0" iyy="0.1" iyz="0.0" izz="0.1"/>
      </inertial>
      <visual>
        <material name="white"/>
        <origin xyz="0 0 0" rpy="0 0 0"/>
        <geometry>
          <box size="0.01 0.35 0.05"/>
        </geometry>
      </visual>
      <collision>
        <geometry>
          <box size="0.01 0.35 0.05"/>
        </geometry>
      </collision>
    </link>

    <!-- links of cylinder base connected with the ee_base -->
    <!-- visual only? DO NOT ERASE THIS!! -->
    <!-- <link name="conveyor_belt_dof1_link">
      <inertial>
        <mass value="1.2"/>
        <origin xyz="0 0 0"/>
        <inertia ixx="1.0" ixy="0.0" ixz="0.0" iyy="1.0" iyz="0.0" izz="1.0"/>
      </inertial>
      <visual>
        <material name="white"/>
        <geometry>
          <mesh filename="../mesh/cbee_gripper_1st-collision.obj" />
        </geometry>
        <origin rpy="0 0 3.14" xyz="0.55 0 -0.1"/>
      </visual>
    </link> -->

    

     <!-- virtual link, equivlent of TCP (Tool Center Point) -->
    <link name="whisker_right_link">
      <inertial>
        <mass value="0.01"/>
        <origin xyz="0 0 0"/>
        <inertia ixx="1.0" ixy="0.0" ixz="0.0" iyy="1.0" iyz="0.0" izz="1.0"/>
      </inertial>
      <visual name="finger1">
        <material name="red"/>
        <geometry>
          <box size="0.08 0.39 0.003"/> 
        </geometry>
        <origin rpy="1.57 0 0" xyz="-0.04125 0 0.195"/>
      </visual>

      <visual name="finger2">
        <material name="red"/>
        <geometry>
          <box size="0.08 0.39 0.003"/> 
        </geometry>
        <origin rpy="1.57 0 0" xyz="0.12375 0 0.195"/>
      </visual>

      <collision name="finger1">
        <geometry>
          <box size="0.08 0.39 0.003"/>
        </geometry>
        <origin rpy="1.57 0 0" xyz="-0.04125 0 0.195"/>
      </collision>

      <collision name="finger2">
        <geometry>
          <box size="0.08 0.39 0.003"/> 
        </geometry>
        <origin rpy="1.57 0 0" xyz="0.12375 0 0.195"/>
      </collision>
    </link>

    <link name="whisker_left_link">
      <inertial>
        <mass value="0.01"/>
        <origin xyz="0 0 0"/>
        <inertia ixx="1.0" ixy="0.0" ixz="0.0" iyy="1.0" iyz="0.0" izz="1.0"/>
      </inertial>

      <visual name="finger1">
        <material name="red"/>
        <geometry>
          <box size="0.08 0.39 0.003"/>
        </geometry>
        <origin rpy="1.57 0 0" xyz="-0.12375 0 0.195"/>
      </visual>

      <visual name="finger2">
        <material name="red"/>
        <geometry>
          <box size="0.08 0.39 0.003"/> 
        </geometry>
        <origin rpy="1.57 0 0" xyz="0.04125 0 0.195"/>
      </visual>

      <collision name="finger1">
        <geometry>
          <box size="0.08 0.39 0.003"/>
        </geometry>
        <origin rpy="1.57 0 0" xyz="-0.12375 0 0.195"/>
      </collision>

      <collision name="finger2">
        <geometry>
          <box size="0.08 0.39 0.003"/> 
        </geometry>
        <origin rpy="1.57 0 0" xyz="0.04125 0 0.195"/>
      </collision>
    </link>

    <link name='right_whisker_offset'>
      <visual name='visual_right_offset'>
        <geometry>
          <box size="0.01 0.01 0.01"/>
        </geometry>
        <material>
          <diffuse>0 1 1 1.0</diffuse>
        </material>
      </visual> 
    </link>

    <link name='left_whisker_offset'>
        <visual name='visual_left_offset'>
        <geometry>
          <box size="0.01 0.01 0.01"/>
        </geometry>
        <material>
          <diffuse>0 1 1 1.0</diffuse>
        </material>
      </visual> 
    </link>

    <link name="roller_base_1">
      <!-- <visual>
        <material name="blue"/>
        <origin xyz="0 0 0" rpy="0 0 0"/>
        <geometry>
          <box size="0.05 0.05 0.05"/>
        </geometry>
      </visual> -->
    </link>

    <link name="roller_base_2">
      <!-- <visual>
        <material name="blue"/>
        <origin xyz="0 0 0" rpy="0 0 0"/>
        <geometry>
          <box size="0.05 0.05 0.05"/>
        </geometry>
      </visual> -->
    </link>

    <link name="roller_base_3">
      <!-- <visual>
        <material name="blue"/>
        <origin xyz="0 0 0" rpy="0 0 0"/>
        <geometry>
          <box size="0.05 0.05 0.05"/>
        </geometry>
      </visual> -->
    </link>

    <link name="roller_base_4">
      <!-- <visual>
        <material name="blue"/>
        <origin xyz="0 0 0" rpy="0 0 0"/>
        <geometry>
          <box size="0.05 0.05 0.05"/>
        </geometry>
      </visual> -->
    </link>

    <link name="roller_base_5">
      <!-- <visual>
        <material name="blue"/>
        <origin xyz="0 0 0" rpy="0 0 0"/>
        <geometry>
          <box size="0.05 0.05 0.05"/>
        </geometry>
      </visual> -->
    </link>

    <link name="roller_base_6">
      <!-- <visual>
        <material name="blue"/>
        <origin xyz="0 0 0" rpy="0 0 0"/>
        <geometry>
          <box size="0.05 0.05 0.05"/>
        </geometry>
      </visual> -->
    </link>   

    <link name="roller_base_7">
      <!-- <visual>
        <material name="blue"/>
        <origin xyz="0 0 0" rpy="0 0 0"/>
        <geometry>
          <box size="0.05 0.05 0.05"/>
        </geometry>
      </visual> -->
    </link>


    <link name="roller_link_1">
      <inertial>
        <mass value="0.001"/>
        <inertia ixx="0.1" ixy="0.0" ixz="0.0" iyy="0.1" iyz="0.0" izz="0.1"/>
      </inertial>
      <visual>
        <material name="green"/>
        <geometry>
          <cylinder radius="0.0175" length="0.43"/>
        </geometry>
      </visual>
      <collision>
        <geometry>
          <cylinder radius="0.0175" length="0.43"/>
        </geometry>
      </collision>
    </link>

    <link name="roller_link_2">
      <inertial>
        <mass value="0.001"/>
        <inertia ixx="0.1" ixy="0.0" ixz="0.0" iyy="0.1" iyz="0.0" izz="0.1"/>
      </inertial>
      <visual>
        <material name="green"/>
        <geometry>
          <cylinder radius="0.0175" length="0.43"/>
           <!-- <box size="0.04 0.04 0.5"/> -->
        </geometry>
      </visual>
      <collision>
        <geometry>
          <cylinder radius="0.0175" length="0.43"/>
        </geometry>
      </collision>
    </link>

    <link name="roller_link_3">
      <inertial>
        <mass value="0.001"/>
        <inertia ixx="0.1" ixy="0.0" ixz="0.0" iyy="0.1" iyz="0.0" izz="0.1"/>
      </inertial>
      <visual>
        <material name="green"/>
        <geometry>
          <cylinder radius="0.0175" length="0.43"/>
           <!-- <box size="0.04 0.04 0.5"/> -->
        </geometry>
      </visual>
      <collision>
        <geometry>
          <cylinder radius="0.0175" length="0.43"/>
        </geometry>
      </collision>
    </link>

    <link name="roller_link_4">
      <inertial>
        <mass value="0.001"/>
        <inertia ixx="0.1" ixy="0.0" ixz="0.0" iyy="0.1" iyz="0.0" izz="0.1"/>
      </inertial>
      <visual>
        <material name="red"/>
        <geometry>
          <!-- <cylinder radius="0.0175" length="0.43"/> -->
          <box size="0.035 0.035 0.43"/>
        </geometry>
      </visual>
      <collision>
        <geometry>
          <cylinder radius="0.0175" length="0.43"/>
        </geometry>
      </collision>
    </link>

    <link name="roller_link_5">
      <inertial>
        <mass value="0.001"/>
        <inertia ixx="0.1" ixy="0.0" ixz="0.0" iyy="0.1" iyz="0.0" izz="0.1"/>
      </inertial>
      <visual>
        <material name="green"/>
        <geometry>
          <cylinder radius="0.0175" length="0.43"/>
        </geometry>
      </visual>
      <collision>
        <geometry>
          <cylinder radius="0.0175" length="0.43"/>
        </geometry>
      </collision>
    </link>

    <link name="roller_link_6">
      <inertial>
        <mass value="0.001"/>
        <inertia ixx="0.1" ixy="0.0" ixz="0.0" iyy="0.1" iyz="0.0" izz="0.1"/>
      </inertial>
      <visual>
        <material name="green"/>
        <geometry>
          <cylinder radius="0.0175" length="0.43"/>
        </geometry>
      </visual>
      <collision>
        <geometry>
          <cylinder radius="0.0175" length="0.43"/>
        </geometry>
      </collision>
    </link>

    <link name="roller_link_7">
      <inertial>
        <mass value="0.001"/>
        <inertia ixx="0.1" ixy="0.0" ixz="0.0" iyy="0.1" iyz="0.0" izz="0.1"/>
      </inertial>
      <visual>
        <material name="green"/>
        <geometry>
          <cylinder radius="0.0175" length="0.43"/>
        </geometry>
      </visual>
      <collision>
        <geometry>
          <cylinder radius="0.0175" length="0.43"/>
        </geometry>
      </collision>
    </link>

    <!-- frame, equivlent of TCP (Tool Center Point) -->
    <frame link="ee_base" name="ee_tip_0" rpy="0 0 0" xyz="0.54 0 0"/>

    <!-- END LINKS -->


    <!-- JOINTS -->
    <joint name="cover_back_to_base" type="fixed">
      <parent link="ee_base"/>
      <child link="cover_back"/>
      <origin xyz="0.075 0 -0.125" rpy="0 0 0"/>
    </joint>

    <joint name="cover_left_to_base" type="fixed">
      <parent link="ee_base"/>
      <child link="cover_left"/>
      <origin xyz="0.25 0.2 -0.125" rpy="0 0 1.57"/>
    </joint>

    <joint name="cover_right_to_base" type="fixed">
      <parent link="ee_base"/>
      <child link="cover_right"/>
      <origin xyz="0.25 -0.2 -0.125" rpy="0 0 1.57"/>
    </joint>

    <joint name="whisker_right_to_base" type="fixed">
      <parent link="ee_base"/>
      <child link="right_whisker_offset"/>
      <origin xyz="0.2 -0.275 -0.1" rpy="0 0 0"/>
    </joint>

    <joint name="whisker_left_to_base" type="fixed">
      <parent link="ee_base"/>
      <child link="left_whisker_offset"/>
      <origin xyz="0.2 0.275 -0.1" rpy="0 0 0"/>
    </joint>

    <!-- joint whisker right -->
    <joint name="whisker_right_joint" type="revolute">
      <parent link="right_whisker_offset"/>
      <child link="whisker_right_link"/>
      <origin xyz="0 0 0" rpy="0 0 0"/>
      <axis xyz="1 0 0"/>
    </joint>

    <!-- joint whisker left -->
    <joint name="whisker_left_joint" type="revolute">
      <parent link="left_whisker_offset"/>
      <child link="whisker_left_link"/>
      <origin xyz="0 0 0" rpy="0 0 0"/>
      <axis xyz="1 0 0"/>
    </joint>

    <!-- Offset from ee_base to roller joint -->
    <joint name="ee_base_to_roller_base_1" type="fixed">
      <parent link="ee_base"/>
      <child link="roller_base_1"/>
      <origin xyz="0.1 0 -0.175" rpy="1.57 0 0"/>
    </joint>

    <joint name="ee_base_to_roller_base_2" type="fixed">
      <parent link="ee_base"/>
      <child link="roller_base_2"/>
      <origin xyz="0.15 0 -0.175" rpy="1.57 0 0"/>
    </joint>

    <joint name="ee_base_to_roller_base_3" type="fixed">
      <parent link="ee_base"/>
      <child link="roller_base_3"/>
      <origin xyz="0.2 0 -0.175" rpy="1.57 0 0"/>
    </joint>

    <joint name="ee_base_to_roller_base_4" type="fixed">
      <parent link="ee_base"/>
      <child link="roller_base_4"/>
      <origin xyz="0.25 0 -0.175" rpy="1.57 0 0"/>
    </joint>

    <joint name="ee_base_to_roller_base_5" type="fixed">
      <parent link="ee_base"/>
      <child link="roller_base_5"/>
      <origin xyz="0.3 0 -0.175" rpy="1.57 0 0"/>
    </joint>

    <joint name="ee_base_to_roller_base_6" type="fixed">
      <parent link="ee_base"/>
      <child link="roller_base_6"/>
      <origin xyz="0.35 0 -0.175" rpy="1.57 0 0"/>
    </joint>

    <joint name="ee_base_to_roller_base_7" type="fixed">
      <parent link="ee_base"/>
      <child link="roller_base_7"/>
      <origin xyz="0.4 0 -0.175" rpy="1.57 0 0"/>
    </joint>



    <!-- Roller joints -->
    <joint name="roller_joint_1" type="revolute">
      <parent link="roller_base_1"/>
      <child link="roller_link_1"/>
      <origin xyz="0 0 0" rpy="0 0 0"/>
      <axis xyz="1 0 0"/>
    </joint>

    <joint name="roller_joint_2" type="revolute">
      <parent link="roller_base_2"/>
      <child link="roller_link_2"/>
      <origin xyz="0 0 0" rpy="0 0 0"/>
      <axis xyz="1 0 0"/>
    </joint>

    <joint name="roller_joint_3" type="revolute">
      <parent link="roller_base_3"/>
      <child link="roller_link_3"/>
      <origin xyz="0 0 0" rpy="0 0 0"/>
      <axis xyz="1 0 0"/>
    </joint>

    <joint name="roller_joint_4" type="revolute">
      <parent link="roller_base_4"/>
      <child link="roller_link_4"/>
      <origin xyz="0 0 0" rpy="0 0 0"/>
      <axis xyz="1 0 0"/>
    </joint>

    <joint name="roller_joint_5" type="revolute">
      <parent link="roller_base_5"/>
      <child link="roller_link_5"/>
      <origin xyz="0 0 0" rpy="0 0 0"/>
      <axis xyz="1 0 0"/>
    </joint>

    <joint name="roller_joint_6" type="revolute">
      <parent link="roller_base_6"/>
      <child link="roller_link_6"/>
      <origin xyz="0 0 0" rpy="0 0 0"/>
      <axis xyz="1 0 0"/>
    </joint>   

    <joint name="roller_joint_7" type="revolute">
      <parent link="roller_base_7"/>
      <child link="roller_link_7"/>
      <origin xyz="0 0 0" rpy="0 0 0"/>
      <axis xyz="1 0 0"/>
    </joint>


    <!-- END JOINTS -->

  <!--Extensions -->
  <!-- Load Gazebo lib and set the robot namespace -->
  <gazebo>
    <plugin filename="libgazebo_ros_control.so" name="gazebo_ros_controller">
      <robotNamespace>/yaskawa_ee</robotNamespace>
    </plugin>
  </gazebo>

  <gazebo reference="ee_base">
    <material>Gazebo/Grey</material>
    <mu1>0.2</mu1>
    <mu2>0.2</mu2>
  </gazebo>

  <gazebo reference="cover">
    <material>Gazebo/Grey</material>
    <mu1>0.2</mu1>
    <mu2>0.2</mu2>
  </gazebo>

  <gazebo reference="whisker_right_offset">
    <material>Gazebo/Grey</material>
    <mu1>0.2</mu1>
    <mu2>0.2</mu2>
  </gazebo> 

  <gazebo reference="whisker_left_offset">
    <material>Gazebo/Grey</material>
    <mu1>0.2</mu1>
    <mu2>0.2</mu2>
  </gazebo> 

  <gazebo reference="whisker_right_link">
    <material>Gazebo/Grey</material>
    <mu1>0.2</mu1>
    <mu2>0.2</mu2>
  </gazebo>  

  <gazebo reference="whisker_left_link">
    <material>Gazebo/Grey</material>
    <mu1>0.2</mu1>
    <mu2>0.2</mu2>
  </gazebo>

  <gazebo reference="roller_link_1">
    <material>Gazebo/Grey</material>
    <mu1>0.2</mu1>
    <mu2>0.2</mu2>
  </gazebo>

  <gazebo reference="roller_link_2">
    <material>Gazebo/Grey</material>
    <mu1>0.2</mu1>
    <mu2>0.2</mu2>
  </gazebo>

  <gazebo reference="roller_link_3">
    <material>Gazebo/Grey</material>
    <mu1>0.2</mu1>
    <mu2>0.2</mu2>
  </gazebo>

  <gazebo reference="roller_link_4">
    <material>Gazebo/Grey</material>
    <mu1>0.2</mu1>
    <mu2>0.2</mu2>
  </gazebo>

  <gazebo reference="roller_link_5">
    <material>Gazebo/Grey</material>
    <mu1>0.2</mu1>
    <mu2>0.2</mu2>
  </gazebo>

  <gazebo reference="roller_link_6">
    <material>Gazebo/Grey</material>
    <mu1>0.2</mu1>
    <mu2>0.2</mu2>
  </gazebo>

  <gazebo reference="roller_link_7">
    <material>Gazebo/Grey</material>
    <mu1>0.2</mu1>
    <mu2>0.2</mu2>
  </gazebo>

  <gazebo reference="roller_base_1">
    <material>Gazebo/Grey</material>
    <mu1>0.2</mu1>
    <mu2>0.2</mu2>
  </gazebo>

  <gazebo reference="roller_base_2">
    <material>Gazebo/Grey</material>
    <mu1>0.2</mu1>
    <mu2>0.2</mu2>
  </gazebo>

  <gazebo reference="roller_base_3">
    <material>Gazebo/Grey</material>
    <mu1>0.2</mu1>
    <mu2>0.2</mu2>
  </gazebo>

  <gazebo reference="roller_base_4">
    <material>Gazebo/Grey</material>
    <mu1>0.2</mu1>
    <mu2>0.2</mu2>
  </gazebo>

  <gazebo reference="roller_base_5">
    <material>Gazebo/Grey</material>
    <mu1>0.2</mu1>
    <mu2>0.2</mu2>
  </gazebo>

  <gazebo reference="roller_base_6">
    <material>Gazebo/Grey</material>
    <mu1>0.2</mu1>
    <mu2>0.2</mu2>
  </gazebo>

  <gazebo reference="roller_base_7">
    <material>Gazebo/Grey</material>
    <mu1>0.2</mu1>
    <mu2>0.2</mu2>
  </gazebo>

  <gazebo reference="ee_tip_0">
    <material>Gazebo/Grey</material>
    <mu1>0.2</mu1>
    <mu2>0.2</mu2>
  </gazebo>



  <transmission name="yaskawa_ee_1">
    <robotNamespace>/yaskawa</robotNamespace>
    <type>transmission_interface/SimpleTransmission</type>
    <joint name="whisker_right_joint">
      <hardwareInterface>PositionJointInterface</hardwareInterface>
    </joint>
    <actuator name="yaskawa_motor_a">
      <hardwareInterface>PositionJointInterface</hardwareInterface>
      <mechanicalReduction>1</mechanicalReduction>
    </actuator>
  </transmission>

  <transmission name="yaskawa_ee_2">
    <robotNamespace>/yaskawa</robotNamespace>
    <type>transmission_interface/SimpleTransmission</type>
    <joint name="whisker_left_joint">
      <hardwareInterface>PositionJointInterface</hardwareInterface>
    </joint>
    <actuator name="yaskawa_motor_b">
      <hardwareInterface>PositionJointInterface</hardwareInterface>
      <mechanicalReduction>1</mechanicalReduction>
    </actuator>
  </transmission>

  <transmission name="roller_transmission_1">
    <robotNamespace>/yaskawa</robotNamespace>
    <type>transmission_interface/SimpleTransmission</type>
    <joint name="roller_joint_1">
      <hardwareInterface>VelocityJointInterface</hardwareInterface>
    </joint>
    <actuator name="yaskawa_motor_1">
      <mechanicalReduction>1</mechanicalReduction>
    </actuator>
  </transmission>

  <transmission name="roller_transmission_2">
    <robotNamespace>/yaskawa</robotNamespace>
    <type>transmission_interface/SimpleTransmission</type>
    <joint name="roller_joint_2">
      <hardwareInterface>VelocityJointInterface</hardwareInterface>
    </joint>
    <actuator name="yaskawa_motor_2">
      <hardwareInterface>PositionJointInterface</hardwareInterface>
      <mechanicalReduction>1</mechanicalReduction>
    </actuator>
  </transmission>

  <transmission name="roller_transmission_3">
    <robotNamespace>/yaskawa</robotNamespace>
    <type>transmission_interface/SimpleTransmission</type>
    <joint name="roller_joint_3">
      <hardwareInterface>VelocityJointInterface</hardwareInterface>
    </joint>
    <actuator name="yaskawa_motor_3">
      <hardwareInterface>PositionJointInterface</hardwareInterface>
      <mechanicalReduction>1</mechanicalReduction>
    </actuator>
  </transmission>

  <transmission name="roller_transmission_4">
    <robotNamespace>/yaskawa</robotNamespace>
    <type>transmission_interface/SimpleTransmission</type>
    <joint name="roller_joint_4">
      <hardwareInterface>VelocityJointInterface</hardwareInterface>
    </joint>
    <actuator name="yaskawa_motor_4">
      <hardwareInterface>PositionJointInterface</hardwareInterface>
      <mechanicalReduction>1</mechanicalReduction>
    </actuator>
  </transmission>

  <transmission name="roller_transmission_5">
    <robotNamespace>/yaskawa</robotNamespace>
    <type>transmission_interface/SimpleTransmission</type>
    <joint name="roller_joint_5">
      <hardwareInterface>VelocityJointInterface</hardwareInterface>
    </joint>
    <actuator name="yaskawa_motor_5">
      <hardwareInterface>PositionJointInterface</hardwareInterface>
      <mechanicalReduction>1</mechanicalReduction>
    </actuator>
  </transmission>

  <transmission name="roller_transmission_6">
    <robotNamespace>/yaskawa</robotNamespace>
    <type>transmission_interface/SimpleTransmission</type>
    <joint name="roller_joint_6">
      <hardwareInterface>VelocityJointInterface</hardwareInterface>
    </joint>
    <actuator name="yaskawa_motor_6">
      <hardwareInterface>PositionJointInterface</hardwareInterface>
      <mechanicalReduction>1</mechanicalReduction>
    </actuator>
  </transmission>

  <transmission name="roller_transmission_7">
    <robotNamespace>/yaskawa</robotNamespace>
    <type>transmission_interface/SimpleTransmission</type>
    <joint name="roller_joint_7">
      <hardwareInterface>VelocityJointInterface</hardwareInterface>
    </joint>
    <actuator name="yaskawa_motor_7">
      <hardwareInterface>PositionJointInterface</hardwareInterface>
      <mechanicalReduction>1</mechanicalReduction>
    </actuator>
  </transmission>

</robot>

